Workbook

Sheet Técnicos
A1: CADASTRO DE TÉCNICOS
A2: Preencha aqui os técnicos. As células amarelas são de preenchimento manual. O 'Código Depósito' é gerado automaticamente e usado para integrar com a aba Controle de Entrega.
A4: Código do Técnico | B4: Código Depósito | C4: Nome do Técnico | D4: Equipe | E4: Situação
A5: MAX06-1001 | B5: =IF(A5="","","DEV"&MID(A5,4,LEN(A5)-3)) -> DEV06-1001 | C5: Carlos Eduardo Lima | D5: MAXIMA | E5: Ativo
A6: MAX06-1002 | B6: =IF(A6="","","DEV"&MID(A6,4,LEN(A6)-3)) -> DEV06-1002 | C6: Rafael Souza Martins | D6: MAXIMA | E6: Ativo
A7: REA06-2001 | B7: =IF(A7="","","DEV"&MID(A7,4,LEN(A7)-3)) -> DEV06-2001 | C7: Bruno Henrique Costa | D7: REAL | E7: Ativo
A8: REA06-2002 | B8: =IF(A8="","","DEV"&MID(A8,4,LEN(A8)-3)) -> DEV06-2002 | C8: Diego Ferreira Alves | D8: REAL | E8: Ativo
A9: GRE06-3001 | B9: =IF(A9="","","DEV"&MID(A9,4,LEN(A9)-3)) -> DEV06-3001 | C9: Marcos Vinícius Rocha | D9: GREGATTI | E9: Ativo
A10: GRE06-3002 | B10: =IF(A10="","","DEV"&MID(A10,4,LEN(A10)-3)) -> DEV06-3002 | C10: Felipe Augusto Nunes | D10: GREGATTI | E10: Ativo
A11: MAX06-1003 | B11: =IF(A11="","","DEV"&MID(A11,4,LEN(A11)-3)) -> DEV06-1003 | C11: Thiago Ramos Silva | D11: MAXIMA | E11: Inativo
A12: REA06-2003 | B12: =IF(A12="","","DEV"&MID(A12,4,LEN(A12)-3)) -> DEV06-2003 | C12: Lucas Pereira Gomes | D12: REAL | E12: Ativo
B36: =IF(A36="","","DEV"&MID(A36,4,LEN(A36)-3))
B37: =IF(A37="","","DEV"&MID(A37,4,LEN(A37)-3))
B38: =IF(A38="","","DEV"&MID(A38,4,LEN(A38)-3))
B39: =IF(A39="","","DEV"&MID(A39,4,LEN(A39)-3))
B40: =IF(A40="","","DEV"&MID(A40,4,LEN(A40)-3))
B41: =IF(A41="","","DEV"&MID(A41,4,LEN(A41)-3))
B42: =IF(A42="","","DEV"&MID(A42,4,LEN(A42)-3))
B43: =IF(A43="","","DEV"&MID(A43,4,LEN(A43)-3))
B44: =IF(A44="","","DEV"&MID(A44,4,LEN(A44)-3))
B45: =IF(A45="","","DEV"&MID(A45,4,LEN(A45)-3))
B46: =IF(A46="","","DEV"&MID(A46,4,LEN(A46)-3))
B47: =IF(A47="","","DEV"&MID(A47,4,LEN(A47)-3))
... B305: =IF(A305="","","DEV"&MID(A305,4,LEN(A305)-3))

Sheet Consulta
A1: CONSULTA DE ENTREGAS POR TÉCNICO E PERÍODO | K1: CONSULTA POR EQUIPAMENTO | R1: CONSULTA POR Nº DE SÉRIE
A2: Selecione o técnico e o período na área amarela. O resumo e a lista abaixo são atualizados automaticamente. Se não escolher datas, o período padrão (01/01/2000 a 31/12/2099) traz todo o histórico do técnico. | K2: Selecione o equipamento e, opcionalmente, um período. O padrão (01/01/2000 a 31/12/2099) traz todo o histórico. | R2: Digite o número de série. O resumo mostra a situação ATUAL (última movimentação); a lista abaixo mostra o HISTÓRICO COMPLETO — todas as entregas desse equipamento ao longo do tempo.
B3: Técnico: | C3: Carlos Eduardo Lima | K3: Equipamento: | L3: I00468 | R3: Nº de série: | S3: FHTT46913810 | AA3: =IF($S$3="","",IFERROR(_xlfn.MAXIFS('Controle de Entrega'!$G$6:$G$1575,'Controle de Entrega'!$D$6:$D$1575,$S$3),"")) -> 46120 | AB3: =IF($S$3="","",IFERROR(SUMPRODUCT(MAX(('Controle de Entrega'!$D$6:$D$1575=$S$3)*('Controle de Entrega'!$G$6:$G$1575=$AA$3)*ROW('Controle de Entrega'!$D$6:$D$1575))),"")) -> 6
B4: Data início: | C4: 46113 | K4: Data início: | L4: 46113
B5: Data fim: | C5: 46142 | K5: Data fim: | L5: 46142 | R5: SITUAÇÃO ATUAL (última movimentação)
R6: Total de movimentações | T6: =IF($S$3="","-",COUNTIF('Controle de Entrega'!$D$6:$D$1575,$S$3)) -> 1
A7: RESUMO | K7: RESUMO | R7: Técnico atual | T7: =IF($S$3="","-",IFERROR(INDEX('Controle de Entrega'!$F:$F,$AB$3),"-")) -> Rafael Souza Martins
B8: Registros encontrados | D8: =IF($C$3="","-",COUNTIFS('Controle de Entrega'!$N$6:$N$1575,$C$3,'Controle de Entrega'!$G$6:$G$1575,">="&$C$4,'Controle de Entrega'!$G$6:$G$1575,"<="&$C$5)) -> 8 | L8: Registros encontrados | N8: =IF($L$3="","-",COUNTIFS('Controle de Entrega'!$C$6:$C$1575,$L$3,'Controle de Entrega'!$G$6:$G$1575,">="&$L$4,'Controle de Entrega'!$G$6:$G$1575,"<="&$L$5)) -> 0 | R8: Nº do item | T8: =IF($S$3="","-",IFERROR(INDEX('Controle de Entrega'!$B:$B,$AB$3),"-")) -> I00468
B9: Quantidade total de equipamentos | D9: =IF($C$3="","-",SUMIFS('Controle de Entrega'!$E$6:$E$1575,'Controle de Entrega'!$N$6:$N$1575,$C$3,'Controle de Entrega'!$G$6:$G$1575,">="&$C$4,'Controle de Entrega'!$G$6:$G$1575,"<="&$C$5)) -> 8 | L9: Quantidade total entregue | N9: =IF($L$3="","-",SUMIFS('Controle de Entrega'!$E$6:$E$1575,'Controle de Entrega'!$C$6:$C$1575,$L$3,'Controle de Entrega'!$G$6:$G$1575,">="&$L$4,'Controle de Entrega'!$G$6:$G$1575,"<="&$L$5)) -> 0 | R9: Descrição do item | T9: =IF($S$3="","-",IFERROR(INDEX('Controle de Entrega'!$C:$C,$AB$3),"-")) -> ROTEADOR TP-LINK WIRELESS AC1200 ARCHER C5W GIGABIT DUAL BAND
B10: Última entrega | D10: =IF(OR($C$3="",$D$8=0),"-",_xlfn.MAXIFS('Controle de Entrega'!$G$6:$G$1575,'Controle de Entrega'!$N$6:$N$1575,$C$3,'Controle de Entrega'!$G$6:$G$1575,">="&$C$4,'Controle de Entrega'!$G$6:$G$1575,"<="&$C$5)) -> 46137 | L10: Última entrega | N10: =IF(OR($L$3="",$N$8=0),"-",_xlfn.MAXIFS('Controle de Entrega'!$G$6:$G$1575,'Controle de Entrega'!$C$6:$C$1575,$L$3,'Controle de Entrega'!$G$6:$G$1575,">="&$L$4,'Controle de Entrega'!$G$6:$G$1575,"<="&$L$5)) -> - | R10: Quantidade | T10: =IF($S$3="","-",IFERROR(INDEX('Controle de Entrega'!$E:$E,$AB$3),"-")) -> 1
A11: DETALHAMENTO | R11: Data da última entrega | T11: =IF($S$3="","-",IFERROR(INDEX('Controle de Entrega'!$G:$G,$AB$3),"-")) -> 46120
A12: Nº | B12: Posição no depósito | C12: Nº do item | D12: Descrição do item | E12: Nº de série | F12: Quantidade | G12: Técnico | H12: Entrega | I12: Nº Documento | J12: Observação | R12: Nº Documento | T12: =IF($S$3="","",IFERROR(IF(INDEX('Controle de Entrega'!$H:$H,$AB$3)=0,"",INDEX('Controle de Entrega'!$H:$H,$AB$3)),"")) -> 2400000
A13: 1 | R13: Observação | T13: =IF($S$3="","",IFERROR(IF(INDEX('Controle de Entrega'!$I:$I,$AB$3)=0,"",INDEX('Controle de Entrega'!$I:$I,$AB$3)),"")) -> CLIENTE
A14: 2
A15: 3
A16: 4
A17: 5
A18: 6
A19: 7
A20: 8
A21: 9
A22: 10
A23: 11
A24: 12
A25: 13
A26: 14 | B26: =IFERROR(INDEX('Controle de Entrega'!$A$6:$A$1575,MATCH($A26,'Controle de Entrega'!$J$6:$J$1575,0)),"") | C26: =IFERROR(INDEX('Controle de Entrega'!$B$6:$B$1575,MATCH($A26,'Controle de Entrega'!$J$6:$J$1575,0)),"") | D26: =IFERROR(INDEX('Controle de Entrega'!$C$6:$C$1575,MATCH($A26,'Controle de Entrega'!$J$6:$J$1575,0)),"") | E26: =IFERROR(INDEX('Controle de Entrega'!$D$6:$D$1575,MATCH($A26,'Controle de Entrega'!$J$6:$J$1575,0)),"") | F26: =IFERROR(INDEX('Controle de Entrega'!$E$6:$E$1575,MATCH($A26,'Controle de Entrega'!$J$6:$J$1575,0)),"") | G26: =IFERROR(INDEX('Controle de Entrega'!$F$6:$F$1575,MATCH($A26,'Controle de Entrega'!$J$6:$J$1575,0)),"") | H26: =IFERROR(INDEX('Controle de Entrega'!$G$6:$G$1575,MATCH($A26,'Controle de Entrega'!$J$6:$J$1575,0)),"") | I26: =IFERROR(IF(INDEX('Controle de Entrega'!$H$6:$H$1575,MATCH($A26,'Controle de Entrega'!$J$6:$J$1575,0))=0,"",INDEX('Controle de Entrega'!$H$6:$H$1575,MATCH($A26,'Controle de Entrega'!$J$6:$J$1575,0))),"") | J26: =IFERROR(IF(INDEX('Controle de Entrega'!$I$6:$I$1575,MATCH($A26,'Controle de Entrega'!$J$6:$J$1575,0))=0,"",INDEX('Controle de Entrega'!$I$6:$I$1575,MATCH($A26,'Controle de Entrega'!$J$6:$J$1575,0))),"")
A27: 15 | B27: =IFERROR(INDEX('Controle de Entrega'!$A$6:$A$1575,MATCH($A27,'Controle de Entrega'!$J$6:$J$1575,0)),"") | C27: =IFERROR(INDEX('Controle de Entrega'!$B$6:$B$1575,MATCH($A27,'Controle de Entrega'!$J$6:$J$1575,0)),"") | D27: =IFERROR(INDEX('Controle de Entrega'!$C$6:$C$1575,MATCH($A27,'Controle de Entrega'!$J$6:$J$1575,0)),"") | E27: =IFERROR(INDEX('Controle de Entrega'!$D$6:$D$1575,MATCH($A27,'Controle de Entrega'!$J$6:$J$1575,0)),"") | F27: =IFERROR(INDEX('Controle de Entrega'!$E$6:$E$1575,MATCH($A27,'Controle de Entrega'!$J$6:$J$1575,0)),"") | G27: =IFERROR(INDEX('Controle de Entrega'!$F$6:$F$1575,MATCH($A27,'Controle de Entrega'!$J$6:$J$1575,0)),"") | H27: =IFERROR(INDEX('Controle de Entrega'!$G$6:$G$1575,MATCH($A27,'Controle de Entrega'!$J$6:$J$1575,0)),"") | I27: =IFERROR(IF(INDEX('Controle de Entrega'!$H$6:$H$1575,MATCH($A27,'Controle de Entrega'!$J$6:$J$1575,0))=0,"",INDEX('Controle de Entrega'!$H$6:$H$1575,MATCH($A27,'Controle de Entrega'!$J$6:$J$1575,0))),"") | J27: =IFERROR(IF(INDEX('Controle de Entrega'!$I$6:$I$1575,MATCH($A27,'Controle de Entrega'!$J$6:$J$1575,0))=0,"",INDEX('Controle de Entrega'!$I$6:$I$1575,MATCH($A27,'Controle de Entrega'!$J$6:$J$1575,0))),"")
A28: 16 | B28: =IFERROR(INDEX('Controle de Entrega'!$A$6:$A$1575,MATCH($A28,'Controle de Entrega'!$J$6:$J$1575,0)),"") | C28: =IFERROR(INDEX('Controle de Entrega'!$B$6:$B$1575,MATCH($A28,'Controle de Entrega'!$J$6:$J$1575,0)),"") | D28: =IFERROR(INDEX('Controle de Entrega'!$C$6:$C$1575,MATCH($A28,'Controle de Entrega'!$J$6:$J$1575,0)),"") | E28: =IFERROR(INDEX('Controle de Entrega'!$D$6:$D$1575,MATCH($A28,'Controle de Entrega'!$J$6:$J$1575,0)),"") | F28: =IFERROR(INDEX('Controle de Entrega'!$E$6:$E$1575,MATCH($A28,'Controle de Entrega'!$J$6:$J$1575,0)),"") | G28: =IFERROR(INDEX('Controle de Entrega'!$F$6:$F$1575,MATCH($A28,'Controle de Entrega'!$J$6:$J$1575,0)),"") | H28: =IFERROR(INDEX('Controle de Entrega'!$G$6:$G$1575,MATCH($A28,'Controle de Entrega'!$J$6:$J$1575,0)),"") | I28: =IFERROR(IF(INDEX('Controle de Entrega'!$H$6:$H$1575,MATCH($A28,'Controle de Entrega'!$J$6:$J$1575,0))=0,"",INDEX('Controle de Entrega'!$H$6:$H$1575,MATCH($A28,'Controle de Entrega'!$J$6:$J$1575,0))),"") | J28: =IFERROR(IF(INDEX('Controle de Entrega'!$I$6:$I$1575,MATCH($A28,'Controle de Entrega'!$J$6:$J$1575,0))=0,"",INDEX('Controle de Entrega'!$I$6:$I$1575,MATCH($A28,'Controle de Entrega'!$J$6:$J$1575,0))),"")
A29: 17 | B29: =IFERROR(INDEX('Controle de Entrega'!$A$6:$A$1575,MATCH($A29,'Controle de Entrega'!$J$6:$J$1575,0)),"") | C29: =IFERROR(INDEX('Controle de Entrega'!$B$6:$B$1575,MATCH($A29,'Controle de Entrega'!$J$6:$J$1575,0)),"") | D29: =IFERROR(INDEX('Controle de Entrega'!$C$6:$C$1575,MATCH($A29,'Controle de Entrega'!$J$6:$J$1575,0)),"") | E29: =IFERROR(INDEX('Controle de Entrega'!$D$6:$D$1575,MATCH($A29,'Controle de Entrega'!$J$6:$J$1575,0)),"") | F29: =IFERROR(INDEX('Controle de Entrega'!$E$6:$E$1575,MATCH($A29,'Controle de Entrega'!$J$6:$J$1575,0)),"") | G29: =IFERROR(INDEX('Controle de Entrega'!$F$6:$F$1575,MATCH($A29,'Controle de Entrega'!$J$6:$J$1575,0)),"") | H29: =IFERROR(INDEX('Controle de Entrega'!$G$6:$G$1575,MATCH($A29,'Controle de Entrega'!$J$6:$J$1575,0)),"") | I29: =IFERROR(IF(INDEX('Controle de Entrega'!$H$6:$H$1575,MATCH($A29,'Controle de Entrega'!$J$6:$J$1575,0))=0,"",INDEX('Controle de Entrega'!$H$6:$H$1575,MATCH($A29,'Controle de Entrega'!$J$6:$J$1575,0))),"") | J29: =IFERROR(IF(INDEX('Controle de Entrega'!$I$6:$I$1575,MATCH($A29,'Controle de Entrega'!$J$6:$J$1575,0))=0,"",INDEX('Controle de Entrega'!$I$6:$I$1575,MATCH($A29,'Controle de Entrega'!$J$6:$J$1575,0))),"")
A30: 18 | B30: =IFERROR(INDEX('Controle de Entrega'!$A$6:$A$1575,MATCH($A30,'Controle de Entrega'!$J$6:$J$1575,0)),"") | C30: =IFERROR(INDEX('Controle de Entrega'!$B$6:$B$1575,MATCH($A30,'Controle de Entrega'!$J$6:$J$1575,0)),"") | D30: =IFERROR(INDEX('Controle de Entrega'!$C$6:$C$1575,MATCH($A30,'Controle de Entrega'!$J$6:$J$1575,0)),"") | E30: =IFERROR(INDEX('Controle de Entrega'!$D$6:$D$1575,MATCH($A30,'Controle de Entrega'!$J$6:$J$1575,0)),"") | F30: =IFERROR(INDEX('Controle de Entrega'!$E$6:$E$1575,MATCH($A30,'Controle de Entrega'!$J$6:$J$1575,0)),"") | G30: =IFERROR(INDEX('Controle de Entrega'!$F$6:$F$1575,MATCH($A30,'Controle de Entrega'!$J$6:$J$1575,0)),"") | H30: =IFERROR(INDEX('Controle de Entrega'!$G$6:$G$1575,MATCH($A30,'Controle de Entrega'!$J$6:$J$1575,0)),"") | I30: =IFERROR(IF(INDEX('Controle de Entrega'!$H$6:$H$1575,MATCH($A30,'Controle de Entrega'!$J$6:$J$1575,0))=0,"",INDEX('Controle de Entrega'!$H$6:$H$1575,MATCH($A30,'Controle de Entrega'!$J$6:$J$1575,0))),"") | J30: =IFERROR(IF(INDEX('Controle de Entrega'!$I$6:$I$1575,MATCH($A30,'Controle de Entrega'!$J$6:$J$1575,0))=0,"",INDEX('Controle de Entrega'!$I$6:$I$1575,MATCH($A30,'Controle de Entrega'!$J$6:$J$1575,0))),"")
A31: 19 | B31: =IFERROR(INDEX('Controle de Entrega'!$A$6:$A$1575,MATCH($A31,'Controle de Entrega'!$J$6:$J$1575,0)),"") | C31: =IFERROR(INDEX('Controle de Entrega'!$B$6:$B$1575,MATCH($A31,'Controle de Entrega'!$J$6:$J$1575,0)),"") | D31: =IFERROR(INDEX('Controle de Entrega'!$C$6:$C$1575,MATCH($A31,'Controle de Entrega'!$J$6:$J$1575,0)),"") | E31: =IFERROR(INDEX('Controle de Entrega'!$D$6:$D$1575,MATCH($A31,'Controle de Entrega'!$J$6:$J$1575,0)),"") | F31: =IFERROR(INDEX('Controle de Entrega'!$E$6:$E$1575,MATCH($A31,'Controle de Entrega'!$J$6:$J$1575,0)),"") | G31: =IFERROR(INDEX('Controle de Entrega'!$F$6:$F$1575,MATCH($A31,'Controle de Entrega'!$J$6:$J$1575,0)),"") | H31: =IFERROR(INDEX('Controle de Entrega'!$G$6:$G$1575,MATCH($A31,'Controle de Entrega'!$J$6:$J$1575,0)),"") | I31: =IFERROR(IF(INDEX('Controle de Entrega'!$H$6:$H$1575,MATCH($A31,'Controle de Entrega'!$J$6:$J$1575,0))=0,"",INDEX('Controle de Entrega'!$H$6:$H$1575,MATCH($A31,'Controle de Entrega'!$J$6:$J$1575,0))),"") | J31: =IFERROR(IF(INDEX('Controle de Entrega'!$I$6:$I$1575,MATCH($A31,'Controle de Entrega'!$J$6:$J$1575,0))=0,"",INDEX('Controle de Entrega'!$I$6:$I$1575,MATCH($A31,'Controle de Entrega'!$J$6:$J$1575,0))),"")
A32: 20 | B32: =IFERROR(INDEX('Controle de Entrega'!$A$6:$A$1575,MATCH($A32,'Controle de Entrega'!$J$6:$J$1575,0)),"") | C32: =IFERROR(INDEX('Controle de Entrega'!$B$6:$B$1575,MATCH($A32,'Controle de Entrega'!$J$6:$J$1575,0)),"") | D32: =IFERROR(INDEX('Controle de Entrega'!$C$6:$C$1575,MATCH($A32,'Controle de Entrega'!$J$6:$J$1575,0)),"") | E32: =IFERROR(INDEX('Controle de Entrega'!$D$6:$D$1575,MATCH($A32,'Controle de Entrega'!$J$6:$J$1575,0)),"") | F32: =IFERROR(INDEX('Controle de Entrega'!$E$6:$E$1575,MATCH($A32,'Controle de Entrega'!$J$6:$J$1575,0)),"") | G32: =IFERROR(INDEX('Controle de Entrega'!$F$6:$F$1575,MATCH($A32,'Controle de Entrega'!$J$6:$J$1575,0)),"") | H32: =IFERROR(INDEX('Controle de Entrega'!$G$6:$G$1575,MATCH($A32,'Controle de Entrega'!$J$6:$J$1575,0)),"") | I32: =IFERROR(IF(INDEX('Controle de Entrega'!$H$6:$H$1575,MATCH($A32,'Controle de Entrega'!$J$6:$J$1575,0))=0,"",INDEX('Controle de Entrega'!$H$6:$H$1575,MATCH($A32,'Controle de Entrega'!$J$6:$J$1575,0))),"") | J32: =IFERROR(IF(INDEX('Controle de Entrega'!$I$6:$I$1575,MATCH($A32,'Controle de Entrega'!$J$6:$J$1575,0))=0,"",INDEX('Controle de Entrega'!$I$6:$I$1575,MATCH($A32,'Controle de Entrega'!$J$6:$J$1575,0))),"")
A33: 21 | B33: =IFERROR(INDEX('Controle de Entrega'!$A$6:$A$1575,MATCH($A33,'Controle de Entrega'!$J$6:$J$1575,0)),"") | C33: =IFERROR(INDEX('Controle de Entrega'!$B$6:$B$1575,MATCH($A33,'Controle de Entrega'!$J$6:$J$1575,0)),"") | D33: =IFERROR(INDEX('Controle de Entrega'!$C$6:$C$1575,MATCH($A33,'Controle de Entrega'!$J$6:$J$1575,0)),"") | E33: =IFERROR(INDEX('Controle de Entrega'!$D$6:$D$1575,MATCH($A33,'Controle de Entrega'!$J$6:$J$1575,0)),"") | F33: =IFERROR(INDEX('Controle de Entrega'!$E$6:$E$1575,MATCH($A33,'Controle de Entrega'!$J$6:$J$1575,0)),"") | G33: =IFERROR(INDEX('Controle de Entrega'!$F$6:$F$1575,MATCH($A33,'Controle de Entrega'!$J$6:$J$1575,0)),"") | H33: =IFERROR(INDEX('Controle de Entrega'!$G$6:$G$1575,MATCH($A33,'Controle de Entrega'!$J$6:$J$1575,0)),"") | I33: =IFERROR(IF(INDEX('Controle de Entrega'!$H$6:$H$1575,MATCH($A33,'Controle de Entrega'!$J$6:$J$1575,0))=0,"",INDEX('Controle de Entrega'!$H$6:$H$1575,MATCH($A33,'Controle de Entrega'!$J$6:$J$1575,0))),"") | J33: =IFERROR(IF(INDEX('Controle de Entrega'!$I$6:$I$1575,MATCH($A33,'Controle de Entrega'!$J$6:$J$1575,0))=0,"",INDEX('Controle de Entrega'!$I$6:$I$1575,MATCH($A33,'Controle de Entrega'!$J$6:$J$1575,0))),"")
A34: 22 | B34: =IFERROR(INDEX('Controle de Entrega'!$A$6:$A$1575,MATCH($A34,'Controle de Entrega'!$J$6:$J$1575,0)),"") | C34: =IFERROR(INDEX('Controle de Entrega'!$B$6:$B$1575,MATCH($A34,'Controle de Entrega'!$J$6:$J$1575,0)),"") | D34: =IFERROR(INDEX('Controle de Entrega'!$C$6:$C$1575,MATCH($A34,'Controle de Entrega'!$J$6:$J$1575,0)),"") | E34: =IFERROR(INDEX('Controle de Entrega'!$D$6:$D$1575,MATCH($A34,'Controle de Entrega'!$J$6:$J$1575,0)),"") | F34: =IFERROR(INDEX('Controle de Entrega'!$E$6:$E$1575,MATCH($A34,'Controle de Entrega'!$J$6:$J$1575,0)),"") | G34: =IFERROR(INDEX('Controle de Entrega'!$F$6:$F$1575,MATCH($A34,'Controle de Entrega'!$J$6:$J$1575,0)),"") | H34: =IFERROR(INDEX('Controle de Entrega'!$G$6:$G$1575,MATCH($A34,'Controle de Entrega'!$J$6:$J$1575,0)),"") | I34: =IFERROR(IF(INDEX('Controle de Entrega'!$H$6:$H$1575,MATCH($A34,'Controle de Entrega'!$J$6:$J$1575,0))=0,"",INDEX('Controle de Entrega'!$H$6:$H$1575,MATCH($A34,'Controle de Entrega'!$J$6:$J$1575,0))),"") | J34: =IFERROR(IF(INDEX('Controle de Entrega'!$I$6:$I$1575,MATCH($A34,'Controle de Entrega'!$J$6:$J$1575,0))=0,"",INDEX('Controle de Entrega'!$I$6:$I$1575,MATCH($A34,'Controle de Entrega'!$J$6:$J$1575,0))),"")
A35: 23 | B35: =IFERROR(INDEX('Controle de Entrega'!$A$6:$A$1575,MATCH($A35,'Controle de Entrega'!$J$6:$J$1575,0)),"") | C35: =IFERROR(INDEX('Controle de Entrega'!$B$6:$B$1575,MATCH($A35,'Controle de Entrega'!$J$6:$J$1575,0)),"") | D35: =IFERROR(INDEX('Controle de Entrega'!$C$6:$C$1575,MATCH($A35,'Controle de Entrega'!$J$6:$J$1575,0)),"") | E35: =IFERROR(INDEX('Controle de Entrega'!$D$6:$D$1575,MATCH($A35,'Controle de Entrega'!$J$6:$J$1575,0)),"") | F35: =IFERROR(INDEX('Controle de Entrega'!$E$6:$E$1575,MATCH($A35,'Controle de Entrega'!$J$6:$J$1575,0)),"") | G35: =IFERROR(INDEX('Controle de Entrega'!$F$6:$F$1575,MATCH($A35,'Controle de Entrega'!$J$6:$J$1575,0)),"") | H35: =IFERROR(INDEX('Controle de Entrega'!$G$6:$G$1575,MATCH($A35,'Controle de Entrega'!$J$6:$J$1575,0)),"") | I35: =IFERROR(IF(INDEX('Controle de Entrega'!$H$6:$H$1575,MATCH($A35,'Controle de Entrega'!$J$6:$J$1575,0))=0,"",INDEX('Controle de Entrega'!$H$6:$H$1575,MATCH($A35,'Controle de Entrega'!$J$6:$J$1575,0))),"") | J35: =IFERROR(IF(INDEX('Controle de Entrega'!$I$6:$I$1575,MATCH($A35,'Controle de Entrega'!$J$6:$J$1575,0))=0,"",INDEX('Controle de Entrega'!$I$6:$I$1575,MATCH($A35,'Controle de Entrega'!$J$6:$J$1575,0))),"")
A36: 24 | B36: =IFERROR(INDEX('Controle de Entrega'!$A$6:$A$1575,MATCH($A36,'Controle de Entrega'!$J$6:$J$1575,0)),"") | C36: =IFERROR(INDEX('Controle de Entrega'!$B$6:$B$1575,MATCH($A36,'Controle de Entrega'!$J$6:$J$1575,0)),"") | D36: =IFERROR(INDEX('Controle de Entrega'!$C$6:$C$1575,MATCH($A36,'Controle de Entrega'!$J$6:$J$1575,0)),"") | E36: =IFERROR(INDEX('Controle de Entrega'!$D$6:$D$1575,MATCH($A36,'Controle de Entrega'!$J$6:$J$1575,0)),"") | F36: =IFERROR(INDEX('Controle de Entrega'!$E$6:$E$1575,MATCH($A36,'Controle de Entrega'!$J$6:$J$1575,0)),"") | G36: =IFERROR(INDEX('Controle de Entrega'!$F$6:$F$1575,MATCH($A36,'Controle de Entrega'!$J$6:$J$1575,0)),"") | H36: =IFERROR(INDEX('Controle de Entrega'!$G$6:$G$1575,MATCH($A36,'Controle de Entrega'!$J$6:$J$1575,0)),"") | I36: =IFERROR(IF(INDEX('Controle de Entrega'!$H$6:$H$1575,MATCH($A36,'Controle de Entrega'!$J$6:$J$1575,0))=0,"",INDEX('Controle de Entrega'!$H$6:$H$1575,MATCH($A36,'Controle de Entrega'!$J$6:$J$1575,0))),"") | J36: =IFERROR(IF(INDEX('Controle de Entrega'!$I$6:$I$1575,MATCH($A36,'Controle de Entrega'!$J$6:$J$1575,0))=0,"",INDEX('Controle de Entrega'!$I$6:$I$1575,MATCH($A36,'Controle de Entrega'!$J$6:$J$1575,0))),"")
A37: 25 | B37: =IFERROR(INDEX('Controle de Entrega'!$A$6:$A$1575,MATCH($A37,'Controle de Entrega'!$J$6:$J$1575,0)),"") | C37: =IFERROR(INDEX('Controle de Entrega'!$B$6:$B$1575,MATCH($A37,'Controle de Entrega'!$J$6:$J$1575,0)),"") | D37: =IFERROR(INDEX('Controle de Entrega'!$C$6:$C$1575,MATCH($A37,'Controle de Entrega'!$J$6:$J$1575,0)),"") | E37: =IFERROR(INDEX('Controle de Entrega'!$D$6:$D$1575,MATCH($A37,'Controle de Entrega'!$J$6:$J$1575,0)),"") | F37: =IFERROR(INDEX('Controle de Entrega'!$E$6:$E$1575,MATCH($A37,'Controle de Entrega'!$J$6:$J$1575,0)),"") | G37: =IFERROR(INDEX('Controle de Entrega'!$F$6:$F$1575,MATCH($A37,'Controle de Entrega'!$J$6:$J$1575,0)),"") | H37: =IFERROR(INDEX('Controle de Entrega'!$G$6:$G$1575,MATCH($A37,'Controle de Entrega'!$J$6:$J$1575,0)),"") | I37: =IFERROR(IF(INDEX('Controle de Entrega'!$H$6:$H$1575,MATCH($A37,'Controle de Entrega'!$J$6:$J$1575,0))=0,"",INDEX('Controle de Entrega'!$H$6:$H$1575,MATCH($A37,'Controle de Entrega'!$J$6:$J$1575,0))),"") | J37: =IFERROR(IF(INDEX('Controle de Entrega'!$I$6:$I$1575,MATCH($A37,'Controle de Entrega'!$J$6:$J$1575,0))=0,"",INDEX('Controle de Entrega'!$I$6:$I$1575,MATCH($A37,'Controle de Entrega'!$J$6:$J$1575,0))),"")
... A92: 80 | B92: =IFERROR(INDEX('Controle de Entrega'!$A$6:$A$1575,MATCH($A92,'Controle de Entrega'!$J$6:$J$1575,0)),"") | C92: =IFERROR(INDEX('Controle de Entrega'!$B$6:$B$1575,MATCH($A92,'Controle de Entrega'!$J$6:$J$1575,0)),"") | D92: =IFERROR(INDEX('Controle de Entrega'!$C$6:$C$1575,MATCH($A92,'Controle de Entrega'!$J$6:$J$1575,0)),"") | E92: =IFERROR(INDEX('Controle de Entrega'!$D$6:$D$1575,MATCH($A92,'Controle de Entrega'!$J$6:$J$1575,0)),"") | F92: =IFERROR(INDEX('Controle de Entrega'!$E$6:$E$1575,MATCH($A92,'Controle de Entrega'!$J$6:$J$1575,0)),"") | G92: =IFERROR(INDEX('Controle de Entrega'!$F$6:$F$1575,MATCH($A92,'Controle de Entrega'!$J$6:$J$1575,0)),"") | H92: =IFERROR(INDEX('Controle de Entrega'!$G$6:$G$1575,MATCH($A92,'Controle de Entrega'!$J$6:$J$1575,0)),"") | I92: =IFERROR(IF(INDEX('Controle de Entrega'!$H$6:$H$1575,MATCH($A92,'Controle de Entrega'!$J$6:$J$1575,0))=0,"",INDEX('Controle de Entrega'!$H$6:$H$1575,MATCH($A92,'Controle de Entrega'!$J$6:$J$1575,0))),"") | J92: =IFERROR(IF(INDEX('Controle de Entrega'!$I$6:$I$1575,MATCH($A92,'Controle de Entrega'!$J$6:$J$1575,0))=0,"",INDEX('Controle de Entrega'!$I$6:$I$1575,MATCH($A92,'Controle de Entrega'!$J$6:$J$1575,0))),"")
A95: DETALHAMENTO POR EQUIPAMENTO | R95: HISTÓRICO COMPLETO DE MOVIMENTAÇÕES DESTA SÉRIE (da mais antiga à mais recente)
A96: Nº | B96: Posição no depósito | C96: Nº do item | D96: Descrição do item | E96: Nº de série | F96: Quantidade | G96: Técnico | H96: Entrega | I96: Nº Documento | J96: Observação | R96: Nº | S96: Posição no depósito | T96: Nº do item | U96: Descrição do item | V96: Nº de série | W96: Quantidade | X96: Técnico | Y96: Entrega | Z96: Nº Documento | AA96: Observação | AB96: Situação
...

Sheet Dashboard
A1: DASHBOARD — ENTREGAS POR PERÍODO
A2: Escolha o período abaixo. As tabelas e os gráficos são recalculados automaticamente com base nos dados da aba 'Controle de Entrega'.
B3: Data início: | C3: 46113 | D3: Data fim: | E3: 46142
A6: Técnico | B6: Quantidade entregue
A7: =Técnicos!$C$5 -> Carlos Eduardo Lima | B7: =SUMIFS('Controle de Entrega'!$E$6:$E$1575,'Controle de Entrega'!$N$6:$N$1575,$A7,'Controle de Entrega'!$G$6:$G$1575,">="&$C$3,'Controle de Entrega'!$G$6:$G$1575,"<="&$E$3) -> 8
A8: =Técnicos!$C$6 -> Rafael Souza Martins | B8: =SUMIFS('Controle de Entrega'!$E$6:$E$1575,'Controle de Entrega'!$N$6:$N$1575,$A8,'Controle de Entrega'!$G$6:$G$1575,">="&$C$3,'Controle de Entrega'!$G$6:$G$1575,"<="&$E$3) -> 7
A9: =Técnicos!$C$7 -> Bruno Henrique Costa | B9: =SUMIFS('Controle de Entrega'!$E$6:$E$1575,'Controle de Entrega'!$N$6:$N$1575,$A9,'Controle de Entrega'!$G$6:$G$1575,">="&$C$3,'Controle de Entrega'!$G$6:$G$1575,"<="&$E$3) -> 3
A10: =Técnicos!$C$8 -> Diego Ferreira Alves | B10: =SUMIFS('Controle de Entrega'!$E$6:$E$1575,'Controle de Entrega'!$N$6:$N$1575,$A10,'Controle de Entrega'!$G$6:$G$1575,">="&$C$3,'Controle de Entrega'!$G$6:$G$1575,"<="&$E$3) -> 7
A11: =Técnicos!$C$9 -> Marcos Vinícius Rocha | B11: =SUMIFS('Controle de Entrega'!$E$6:$E$1575,'Controle de Entrega'!$N$6:$N$1575,$A11,'Controle de Entrega'!$G$6:$G$1575,">="&$C$3,'Controle de Entrega'!$G$6:$G$1575,"<="&$E$3) -> 3
A12: =Técnicos!$C$10 -> Felipe Augusto Nunes | B12: =SUMIFS('Controle de Entrega'!$E$6:$E$1575,'Controle de Entrega'!$N$6:$N$1575,$A12,'Controle de Entrega'!$G$6:$G$1575,">="&$C$3,'Controle de Entrega'!$G$6:$G$1575,"<="&$E$3) -> 7
A13: =Técnicos!$C$11 -> Thiago Ramos Silva | B13: =SUMIFS('Controle de Entrega'!$E$6:$E$1575,'Controle de Entrega'!$N$6:$N$1575,$A13,'Controle de Entrega'!$G$6:$G$1575,">="&$C$3,'Controle de Entrega'!$G$6:$G$1575,"<="&$E$3) -> 2
A14: =Técnicos!$C$12 -> Lucas Pereira Gomes | B14: =SUMIFS('Controle de Entrega'!$E$6:$E$1575,'Controle de Entrega'!$N$6:$N$1575,$A14,'Controle de Entrega'!$G$6:$G$1575,">="&$C$3,'Controle de Entrega'!$G$6:$G$1575,"<="&$E$3) -> 3
A15: =Técnicos!$C$13 -> 0 | B15: =SUMIFS('Controle de Entrega'!$E$6:$E$1575,'Controle de Entrega'!$N$6:$N$1575,$A15,'Controle de Entrega'!$G$6:$G$1575,">="&$C$3,'Controle de Entrega'!$G$6:$G$1575,"<="&$E$3) -> 0
A16: =Técnicos!$C$14 -> 0 | B16: =SUMIFS('Controle de Entrega'!$E$6:$E$1575,'Controle de Entrega'!$N$6:$N$1575,$A16,'Controle de Entrega'!$G$6:$G$1575,">="&$C$3,'Controle de Entrega'!$G$6:$G$1575,"<="&$E$3) -> 0
A17: =Técnicos!$C$15 -> 0 | B17: =SUMIFS('Controle de Entrega'!$E$6:$E$1575,'Controle de Entrega'!$N$6:$N$1575,$A17,'Controle de Entrega'!$G$6:$G$1575,">="&$C$3,'Controle de Entrega'!$G$6:$G$1575,"<="&$E$3) -> 0
A18: =Técnicos!$C$16 -> 0 | B18: =SUMIFS('Controle de Entrega'!$E$6:$E$1575,'Controle de Entrega'!$N$6:$N$1575,$A18,'Controle de Entrega'!$G$6:$G$1575,">="&$C$3,'Controle de Entrega'!$G$6:$G$1575,"<="&$E$3) -> 0
A19: =Técnicos!$C$17 -> 0 | B19: =SUMIFS('Controle de Entrega'!$E$6:$E$1575,'Controle de Entrega'!$N$6:$N$1575,$A19,'Controle de Entrega'!$G$6:$G$1575,">="&$C$3,'Controle de Entrega'!$G$6:$G$1575,"<="&$E$3) -> 0
A20: =Técnicos!$C$18 -> 0 | B20: =SUMIFS('Controle de Entrega'!$E$6:$E$1575,'Controle de Entrega'!$N$6:$N$1575,$A20,'Controle de Entrega'!$G$6:$G$1575,">="&$C$3,'Controle de Entrega'!$G$6:$G$1575,"<="&$E$3) -> 0
A21: =Técnicos!$C$19 -> 0 | B21: =SUMIFS('Controle de Entrega'!$E$6:$E$1575,'Controle de Entrega'!$N$6:$N$1575,$A21,'Controle de Entrega'!$G$6:$G$1575,">="&$C$3,'Controle de Entrega'!$G$6:$G$1575,"<="&$E$3) -> 0
A22: =Técnicos!$C$20 -> 0 | B22: =SUMIFS('Controle de Entrega'!$E$6:$E$1575,'Controle de Entrega'!$N$6:$N$1575,$A22,'Controle de Entrega'!$G$6:$G$1575,">="&$C$3,'Controle de Entrega'!$G$6:$G$1575,"<="&$E$3) -> 0
A23: =Técnicos!$C$21 -> 0 | B23: =SUMIFS('Controle de Entrega'!$E$6:$E$1575,'Controle de Entrega'!$N$6:$N$1575,$A23,'Controle de Entrega'!$G$6:$G$1575,">="&$C$3,'Controle de Entrega'!$G$6:$G$1575,"<="&$E$3) -> 0
A24: =Técnicos!$C$22 -> 0 | B24: =SUMIFS('Controle de Entrega'!$E$6:$E$1575,'Controle de Entrega'!$N$6:$N$1575,$A24,'Controle de Entrega'!$G$6:$G$1575,">="&$C$3,'Controle de Entrega'!$G$6:$G$1575,"<="&$E$3) -> 0
A25: =Técnicos!$C$23 -> 0 | B25: =SUMIFS('Controle de Entrega'!$E$6:$E$1575,'Controle de Entrega'!$N$6:$N$1575,$A25,'Controle de Entrega'!$G$6:$G$1575,">="&$C$3,'Controle de Entrega'!$G$6:$G$1575,"<="&$E$3) -> 0
A26: =Técnicos!$C$24 -> 0 | B26: =SUMIFS('Controle de Entrega'!$E$6:$E$1575,'Controle de Entrega'!$N$6:$N$1575,$A26,'Controle de Entrega'!$G$6:$G$1575,">="&$C$3,'Controle de Entrega'!$G$6:$G$1575,"<="&$E$3) -> 0
A27: =Técnicos!$C$25 -> 0 | B27: =SUMIFS('Controle de Entrega'!$E$6:$E$1575,'Controle de Entrega'!$N$6:$N$1575,$A27,'Controle de Entrega'!$G$6:$G$1575,">="&$C$3,'Controle de Entrega'!$G$6:$G$1575,"<="&$E$3) -> 0
A28: =Técnicos!$C$26 -> 0 | B28: =SUMIFS('Controle de Entrega'!$E$6:$E$1575,'Controle de Entrega'!$N$6:$N$1575,$A28,'Controle de Entrega'!$G$6:$G$1575,">="&$C$3,'Controle de Entrega'!$G$6:$G$1575,"<="&$E$3) -> 0
A29: =Técnicos!$C$27 -> 0 | B29: =SUMIFS('Controle de Entrega'!$E$6:$E$1575,'Controle de Entrega'!$N$6:$N$1575,$A29,'Controle de Entrega'!$G$6:$G$1575,">="&$C$3,'Controle de Entrega'!$G$6:$G$1575,"<="&$E$3) -> 0
A30: =Técnicos!$C$28 -> 0 | B30: =SUMIFS('Controle de Entrega'!$E$6:$E$1575,'Controle de Entrega'!$N$6:$N$1575,$A30,'Controle de Entrega'!$G$6:$G$1575,">="&$C$3,'Controle de Entrega'!$G$6:$G$1575,"<="&$E$3) -> 0
A31: =Técnicos!$C$29 -> 0 | B31: =SUMIFS('Controle de Entrega'!$E$6:$E$1575,'Controle de Entrega'!$N$6:$N$1575,$A31,'Controle de Entrega'!$G$6:$G$1575,">="&$C$3,'Controle de Entrega'!$G$6:$G$1575,"<="&$E$3) -> 0
A32: =Técnicos!$C$30 -> 0 | B32: =SUMIFS('Controle de Entrega'!$E$6:$E$1575,'Controle de Entrega'!$N$6:$N$1575,$A32,'Controle de Entrega'!$G$6:$G$1575,">="&$C$3,'Controle de Entrega'!$G$6:$G$1575,"<="&$E$3) -> 0
A33: =Técnicos!$C$31 -> 0 | B33: =SUMIFS('Controle de Entrega'!$E$6:$E$1575,'Controle de Entrega'!$N$6:$N$1575,$A33,'Controle de Entrega'!$G$6:$G$1575,">="&$C$3,'Controle de Entrega'!$G$6:$G$1575,"<="&$E$3) -> 0
A34: =Técnicos!$C$32 -> 0 | B34: =SUMIFS('Controle de Entrega'!$E$6:$E$1575,'Controle de Entrega'!$N$6:$N$1575,$A34,'Controle de Entrega'!$G$6:$G$1575,">="&$C$3,'Controle de Entrega'!$G$6:$G$1575,"<="&$E$3) -> 0
A35: =Técnicos!$C$33 -> 0 | B35: =SUMIFS('Controle de Entrega'!$E$6:$E$1575,'Controle de Entrega'!$N$6:$N$1575,$A35,'Controle de Entrega'!$G$6:$G$1575,">="&$C$3,'Controle de Entrega'!$G$6:$G$1575,"<="&$E$3) -> 0
A36: =Técnicos!$C$34 -> 0 | B36: =SUMIFS('Controle de Entrega'!$E$6:$E$1575,'Controle de Entrega'!$N$6:$N$1575,$A36,'Controle de Entrega'!$G$6:$G$1575,">="&$C$3,'Controle de Entrega'!$G$6:$G$1575,"<="&$E$3) -> 0
A37: =Técnicos!$C$35 -> 0 | B37: =SUMIFS('Controle de Entrega'!$E$6:$E$1575,'Controle de Entrega'!$N$6:$N$1575,$A37,'Controle de Entrega'!$G$6:$G$1575,">="&$C$3,'Controle de Entrega'!$G$6:$G$1575,"<="&$E$3) -> 0
A39: EQUIPAMENTOS ENTREGUES NO PERÍODO
A40: Descrição do equipamento | B40: Quantidade entregue
A41: =Catálogo_Itens!$D$2 -> FIBERHOME ONU HG6143D GPON WI-FI AC 1200M | B41: =SUMIFS('Controle de Entrega'!$E$6:$E$1575,'Controle de Entrega'!$C$6:$C$1575,$A41,'Controle de Entrega'!$G$6:$G$1575,">="&$C$3,'Controle de Entrega'!$G$6:$G$1575,"<="&$E$3) -> 0
A42: =Catálogo_Itens!$D$3 -> FIBRA | B42: =SUMIFS('Controle de Entrega'!$E$6:$E$1575,'Controle de Entrega'!$C$6:$C$1575,$A42,'Controle de Entrega'!$G$6:$G$1575,">="&$C$3,'Controle de Entrega'!$G$6:$G$1575,"<="&$E$3) -> 0
A43: =Catálogo_Itens!$D$4 -> ONT ECHOLIFE HG8145V5 GPON/EPON SC/APC | B43: =SUMIFS('Controle de Entrega'!$E$6:$E$1575,'Controle de Entrega'!$C$6:$C$1575,$A43,'Controle de Entrega'!$G$6:$G$1575,">="&$C$3,'Controle de Entrega'!$G$6:$G$1575,"<="&$E$3) -> 0
...

Sheet Comprovante DEV
B4: COMPROVANTE DE DEVOLUÇÃO DE EQUIPAMENTOS
B5: Selecione o técnico e a data da entrega. A lista é preenchida automaticamente e, na impressão, somente os itens realmente entregues aparecem — as linhas sem equipamento ficam em branco, sem bordas.
C6: Técnico: | D6: Carlos Eduardo Lima
C7: Data da entrega: | D7: 46117
B9: Data por extenso: | C9: =IF($D$7="","",TEXT(DAY($D$7),"0")&" de "&CHOOSE(MONTH($D$7),"janeiro","fevereiro","março","abril","maio","junho","julho","agosto","setembro","outubro","novembro","dezembro")&" de "&YEAR($D$7)) -> 5 de abril de 2026
B11: Nº | C11: Posição no depósito | D11: Nº do item | E11: Descrição do item | F11: Nº de série | G11: Quantidade | H11: Nº Documento | I11: Observação
B12: 1 | C12: =IFERROR(INDEX('Controle de Entrega'!$A$6:$A$1575,MATCH($B12,'Controle de Entrega'!$M$6:$M$1575,0)),"") | D12: =IFERROR(INDEX('Controle de Entrega'!$B$6:$B$1575,MATCH($B12,'Controle de Entrega'!$M$6:$M$1575,0)),"") | E12: =IFERROR(INDEX('Controle de Entrega'!$C$6:$C$1575,MATCH($B12,'Controle de Entrega'!$M$6:$M$1575,0)),"") | F12: =IFERROR(INDEX('Controle de Entrega'!$D$6:$D$1575,MATCH($B12,'Controle de Entrega'!$M$6:$M$1575,0)),"") | G12: =IFERROR(INDEX('Controle de Entrega'!$E$6:$E$1575,MATCH($B12,'Controle de Entrega'!$M$6:$M$1575,0)),"") | H12: =IFERROR(IF(INDEX('Controle de Entrega'!$H$6:$H$1575,MATCH($B12,'Controle de Entrega'!$M$6:$M$1575,0))=0,"",INDEX('Controle de Entrega'!$H$6:$H$1575,MATCH($B12,'Controle de Entrega'!$M$6:$M$1575,0))),"") | I12: =IFERROR(IF(INDEX('Controle de Entrega'!$I$6:$I$1575,MATCH($B12,'Controle de Entrega'!$M$6:$M$1575,0))=0,"",INDEX('Controle de Entrega'!$I$6:$I$1575,MATCH($B12,'Controle de Entrega'!$M$6:$M$1575,0))),"")
B13: 2 | C13: =IFERROR(INDEX('Controle de Entrega'!$A$6:$A$1575,MATCH($B13,'Controle de Entrega'!$M$6:$M$1575,0)),"") | D13: =IFERROR(INDEX('Controle de Entrega'!$B$6:$B$1575,MATCH($B13,'Controle de Entrega'!$M$6:$M$1575,0)),"") | E13: =IFERROR(INDEX('Controle de Entrega'!$C$6:$C$1575,MATCH($B13,'Controle de Entrega'!$M$6:$M$1575,0)),"") | F13: =IFERROR(INDEX('Controle de Entrega'!$D$6:$D$1575,MATCH($B13,'Controle de Entrega'!$M$6:$M$1575,0)),"") | G13: =IFERROR(INDEX('Controle de Entrega'!$E$6:$E$1575,MATCH($B13,'Controle de Entrega'!$M$6:$M$1575,0)),"") | H13: =IFERROR(IF(INDEX('Controle de Entrega'!$H$6:$H$1575,MATCH($B13,'Controle de Entrega'!$M$6:$M$1575,0))=0,"",INDEX('Controle de Entrega'!$H$6:$H$1575,MATCH($B13,'Controle de Entrega'!$M$6:$M$1575,0))),"") | I13: =IFERROR(IF(INDEX('Controle de Entrega'!$I$6:$I$1575,MATCH($B13,'Controle de Entrega'!$M$6:$M$1575,0))=0,"",INDEX('Controle de Entrega'!$I$6:$I$1575,MATCH($B13,'Controle de Entrega'!$M$6:$M$1575,0))),"")
B14: 3 | C14: =IFERROR(INDEX('Controle de Entrega'!$A$6:$A$1575,MATCH($B14,'Controle de Entrega'!$M$6:$M$1575,0)),"") | D14: =IFERROR(INDEX('Controle de Entrega'!$B$6:$B$1575,MATCH($B14,'Controle de Entrega'!$M$6:$M$1575,0)),"") | E14: =IFERROR(INDEX('Controle de Entrega'!$C$6:$C$1575,MATCH($B14,'Controle de Entrega'!$M$6:$M$1575,0)),"") | F14: =IFERROR(INDEX('Controle de Entrega'!$D$6:$D$1575,MATCH($B14,'Controle de Entrega'!$M$6:$M$1575,0)),"") | G14: =IFERROR(INDEX('Controle de Entrega'!$E$6:$E$1575,MATCH($B14,'Controle de Entrega'!$M$6:$M$1575,0)),"") | H14: =IFERROR(IF(INDEX('Controle de Entrega'!$H$6:$H$1575,MATCH($B14,'Controle de Entrega'!$M$6:$M$1575,0))=0,"",INDEX('Controle de Entrega'!$H$6:$H$1575,MATCH($B14,'Controle de Entrega'!$M$6:$M$1575,0))),"") | I14: =IFERROR(IF(INDEX('Controle de Entrega'!$I$6:$I$1575,MATCH($B14,'Controle de Entrega'!$M$6:$M$1575,0))=0,"",INDEX('Controle de Entrega'!$I$6:$I$1575,MATCH($B14,'Controle de Entrega'!$M$6:$M$1575,0))),"")
B15: 4 | C15: =IFERROR(INDEX('Controle de Entrega'!$A$6:$A$1575,MATCH($B15,'Controle de Entrega'!$M$6:$M$1575,0)),"") | D15: =IFERROR(INDEX('Controle de Entrega'!$B$6:$B$1575,MATCH($B15,'Controle de Entrega'!$M$6:$M$1575,0)),"") | E15: =IFERROR(INDEX('Controle de Entrega'!$C$6:$C$1575,MATCH($B15,'Controle de Entrega'!$M$6:$M$1575,0)),"") | F15: =IFERROR(INDEX('Controle de Entrega'!$D$6:$D$1575,MATCH($B15,'Controle de Entrega'!$M$6:$M$1575,0)),"") | G15: =IFERROR(INDEX('Controle de Entrega'!$E$6:$E$1575,MATCH($B15,'Controle de Entrega'!$M$6:$M$1575,0)),"") | H15: =IFERROR(IF(INDEX('Controle de Entrega'!$H$6:$H$1575,MATCH($B15,'Controle de Entrega'!$M$6:$M$1575,0))=0,"",INDEX('Controle de Entrega'!$H$6:$H$1575,MATCH($B15,'Controle de Entrega'!$M$6:$M$1575,0))),"") | I15: =IFERROR(IF(INDEX('Controle de Entrega'!$I$6:$I$1575,MATCH($B15,'Controle de Entrega'!$M$6:$M$1575,0))=0,"",INDEX('Controle de Entrega'!$I$6:$I$1575,MATCH($B15,'Controle de Entrega'!$M$6:$M$1575,0))),"")
B16: 5 | C16: =IFERROR(INDEX('Controle de Entrega'!$A$6:$A$1575,MATCH($B16,'Controle de Entrega'!$M$6:$M$1575,0)),"") | D16: =IFERROR(INDEX('Controle de Entrega'!$B$6:$B$1575,MATCH($B16,'Controle de Entrega'!$M$6:$M$1575,0)),"") | E16: =IFERROR(INDEX('Controle de Entrega'!$C$6:$C$1575,MATCH($B16,'Controle de Entrega'!$M$6:$M$1575,0)),"") | F16: =IFERROR(INDEX('Controle de Entrega'!$D$6:$D$1575,MATCH($B16,'Controle de Entrega'!$M$6:$M$1575,0)),"") | G16: =IFERROR(INDEX('Controle de Entrega'!$E$6:$E$1575,MATCH($B16,'Controle de Entrega'!$M$6:$M$1575,0)),"") | H16: =IFERROR(IF(INDEX('Controle de Entrega'!$H$6:$H$1575,MATCH($B16,'Controle de Entrega'!$M$6:$M$1575,0))=0,"",INDEX('Controle de Entrega'!$H$6:$H$1575,MATCH($B16,'Controle de Entrega'!$M$6:$M$1575,0))),"") | I16: =IFERROR(IF(INDEX('Controle de Entrega'!$I$6:$I$1575,MATCH($B16,'Controle de Entrega'!$M$6:$M$1575,0))=0,"",INDEX('Controle de Entrega'!$I$6:$I$1575,MATCH($B16,'Controle de Entrega'!$M$6:$M$1575,0))),"")
B17: 6 | C17: =IFERROR(INDEX('Controle de Entrega'!$A$6:$A$1575,MATCH($B17,'Controle de Entrega'!$M$6:$M$1575,0)),"") | D17: =IFERROR(INDEX('Controle de Entrega'!$B$6:$B$1575,MATCH($B17,'Controle de Entrega'!$M$6:$M$1575,0)),"") | E17: =IFERROR(INDEX('Controle de Entrega'!$C$6:$C$1575,MATCH($B17,'Controle de Entrega'!$M$6:$M$1575,0)),"") | F17: =IFERROR(INDEX('Controle de Entrega'!$D$6:$D$1575,MATCH($B17,'Controle de Entrega'!$M$6:$M$1575,0)),"") | G17: =IFERROR(INDEX('Controle de Entrega'!$E$6:$E$1575,MATCH($B17,'Controle de Entrega'!$M$6:$M$1575,0)),"") | H17: =IFERROR(IF(INDEX('Controle de Entrega'!$H$6:$H$1575,MATCH($B17,'Controle de Entrega'!$M$6:$M$1575,0))=0,"",INDEX('Controle de Entrega'!$H$6:$H$1575,MATCH($B17,'Controle de Entrega'!$M$6:$M$1575,0))),"") | I17: =IFERROR(IF(INDEX('Controle de Entrega'!$I$6:$I$1575,MATCH($B17,'Controle de Entrega'!$M$6:$M$1575,0))=0,"",INDEX('Controle de Entrega'!$I$6:$I$1575,MATCH($B17,'Controle de Entrega'!$M$6:$M$1575,0))),"")
B18: 7 | C18: =IFERROR(INDEX('Controle de Entrega'!$A$6:$A$1575,MATCH($B18,'Controle de Entrega'!$M$6:$M$1575,0)),"") | D18: =IFERROR(INDEX('Controle de Entrega'!$B$6:$B$1575,MATCH($B18,'Controle de Entrega'!$M$6:$M$1575,0)),"") | E18: =IFERROR(INDEX('Controle de Entrega'!$C$6:$C$1575,MATCH($B18,'Controle de Entrega'!$M$6:$M$1575,0)),"") | F18: =IFERROR(INDEX('Controle de Entrega'!$D$6:$D$1575,MATCH($B18,'Controle de Entrega'!$M$6:$M$1575,0)),"") | G18: =IFERROR(INDEX('Controle de Entrega'!$E$6:$E$1575,MATCH($B18,'Controle de Entrega'!$M$6:$M$1575,0)),"") | H18: =IFERROR(IF(INDEX('Controle de Entrega'!$H$6:$H$1575,MATCH($B18,'Controle de Entrega'!$M$6:$M$1575,0))=0,"",INDEX('Controle de Entrega'!$H$6:$H$1575,MATCH($B18,'Controle de Entrega'!$M$6:$M$1575,0))),"") | I18: =IFERROR(IF(INDEX('Controle de Entrega'!$I$6:$I$1575,MATCH($B18,'Controle de Entrega'!$M$6:$M$1575,0))=0,"",INDEX('Controle de Entrega'!$I$6:$I$1575,MATCH($B18,'Controle de Entrega'!$M$6:$M$1575,0))),"")
B19: 8 | C19: =IFERROR(INDEX('Controle de Entrega'!$A$6:$A$1575,MATCH($B19,'Controle de Entrega'!$M$6:$M$1575,0)),"") | D19: =IFERROR(INDEX('Controle de Entrega'!$B$6:$B$1575,MATCH($B19,'Controle de Entrega'!$M$6:$M$1575,0)),"") | E19: =IFERROR(INDEX('Controle de Entrega'!$C$6:$C$1575,MATCH($B19,'Controle de Entrega'!$M$6:$M$1575,0)),"") | F19: =IFERROR(INDEX('Controle de Entrega'!$D$6:$D$1575,MATCH($B19,'Controle de Entrega'!$M$6:$M$1575,0)),"") | G19: =IFERROR(INDEX('Controle de Entrega'!$E$6:$E$1575,MATCH($B19,'Controle de Entrega'!$M$6:$M$1575,0)),"") | H19: =IFERROR(IF(INDEX('Controle de Entrega'!$H$6:$H$1575,MATCH($B19,'Controle de Entrega'!$M$6:$M$1575,0))=0,"",INDEX('Controle de Entrega'!$H$6:$H$1575,MATCH($B19,'Controle de Entrega'!$M$6:$M$1575,0))),"") | I19: =IFERROR(IF(INDEX('Controle de Entrega'!$I$6:$I$1575,MATCH($B19,'Controle de Entrega'!$M$6:$M$1575,0))=0,"",INDEX('Controle de Entrega'!$I$6:$I$1575,MATCH($B19,'Controle de Entrega'!$M$6:$M$1575,0))),"")
B20: 9 | C20: =IFERROR(INDEX('Controle de Entrega'!$A$6:$A$1575,MATCH($B20,'Controle de Entrega'!$M$6:$M$1575,0)),"") | D20: =IFERROR(INDEX('Controle de Entrega'!$B$6:$B$1575,MATCH($B20,'Controle de Entrega'!$M$6:$M$1575,0)),"") | E20: =IFERROR(INDEX('Controle de Entrega'!$C$6:$C$1575,MATCH($B20,'Controle de Entrega'!$M$6:$M$1575,0)),"") | F20: =IFERROR(INDEX('Controle de Entrega'!$D$6:$D$1575,MATCH($B20,'Controle de Entrega'!$M$6:$M$1575,0)),"") | G20: =IFERROR(INDEX('Controle de Entrega'!$E$6:$E$1575,MATCH($B20,'Controle de Entrega'!$M$6:$M$1575,0)),"") | H20: =IFERROR(IF(INDEX('Controle de Entrega'!$H$6:$H$1575,MATCH($B20,'Controle de Entrega'!$M$6:$M$1575,0))=0,"",INDEX('Controle de Entrega'!$H$6:$H$1575,MATCH($B20,'Controle de Entrega'!$M$6:$M$1575,0))),"") | I20: =IFERROR(IF(INDEX('Controle de Entrega'!$I$6:$I$1575,MATCH($B20,'Controle de Entrega'!$M$6:$M$1575,0))=0,"",INDEX('Controle de Entrega'!$I$6:$I$1575,MATCH($B20,'Controle de Entrega'!$M$6:$M$1575,0))),"")
B21: 10 | C21: =IFERROR(INDEX('Controle de Entrega'!$A$6:$A$1575,MATCH($B21,'Controle de Entrega'!$M$6:$M$1575,0)),"") | D21: =IFERROR(INDEX('Controle de Entrega'!$B$6:$B$1575,MATCH($B21,'Controle de Entrega'!$M$6:$M$1575,0)),"") | E21: =IFERROR(INDEX('Controle de Entrega'!$C$6:$C$1575,MATCH($B21,'Controle de Entrega'!$M$6:$M$1575,0)),"") | F21: =IFERROR(INDEX('Controle de Entrega'!$D$6:$D$1575,MATCH($B21,'Controle de Entrega'!$M$6:$M$1575,0)),"") | G21: =IFERROR(INDEX('Controle de Entrega'!$E$6:$E$1575,MATCH($B21,'Controle de Entrega'!$M$6:$M$1575,0)),"") | H21: =IFERROR(IF(INDEX('Controle de Entrega'!$H$6:$H$1575,MATCH($B21,'Controle de Entrega'!$M$6:$M$1575,0))=0,"",INDEX('Controle de Entrega'!$H$6:$H$1575,MATCH($B21,'Controle de Entrega'!$M$6:$M$1575,0))),"") | I21: =IFERROR(IF(INDEX('Controle de Entrega'!$I$6:$I$1575,MATCH($B21,'Controle de Entrega'!$M$6:$M$1575,0))=0,"",INDEX('Controle de Entrega'!$I$6:$I$1575,MATCH($B21,'Controle de Entrega'!$M$6:$M$1575,0))),"")
B22: 11 | C22: =IFERROR(INDEX('Controle de Entrega'!$A$6:$A$1575,MATCH($B22,'Controle de Entrega'!$M$6:$M$1575,0)),"") | D22: =IFERROR(INDEX('Controle de Entrega'!$B$6:$B$1575,MATCH($B22,'Controle de Entrega'!$M$6:$M$1575,0)),"") | E22: =IFERROR(INDEX('Controle de Entrega'!$C$6:$C$1575,MATCH($B22,'Controle de Entrega'!$M$6:$M$1575,0)),"") | F22: =IFERROR(INDEX('Controle de Entrega'!$D$6:$D$1575,MATCH($B22,'Controle de Entrega'!$M$6:$M$1575,0)),"") | G22: =IFERROR(INDEX('Controle de Entrega'!$E$6:$E$1575,MATCH($B22,'Controle de Entrega'!$M$6:$M$1575,0)),"") | H22: =IFERROR(IF(INDEX('Controle de Entrega'!$H$6:$H$1575,MATCH($B22,'Controle de Entrega'!$M$6:$M$1575,0))=0,"",INDEX('Controle de Entrega'!$H$6:$H$1575,MATCH($B22,'Controle de Entrega'!$M$6:$M$1575,0))),"") | I22: =IFERROR(IF(INDEX('Controle de Entrega'!$I$6:$I$1575,MATCH($B22,'Controle de Entrega'!$M$6:$M$1575,0))=0,"",INDEX('Controle de Entrega'!$I$6:$I$1575,MATCH($B22,'Controle de Entrega'!$M$6:$M$1575,0))),"")
B23: 12 | C23: =IFERROR(INDEX('Controle de Entrega'!$A$6:$A$1575,MATCH($B23,'Controle de Entrega'!$M$6:$M$1575,0)),"") | D23: =IFERROR(INDEX('Controle de Entrega'!$B$6:$B$1575,MATCH($B23,'Controle de Entrega'!$M$6:$M$1575,0)),"") | E23: =IFERROR(INDEX('Controle de Entrega'!$C$6:$C$1575,MATCH($B23,'Controle de Entrega'!$M$6:$M$1575,0)),"") | F23: =IFERROR(INDEX('Controle de Entrega'!$D$6:$D$1575,MATCH($B23,'Controle de Entrega'!$M$6:$M$1575,0)),"") | G23: =IFERROR(INDEX('Controle de Entrega'!$E$6:$E$1575,MATCH($B23,'Controle de Entrega'!$M$6:$M$1575,0)),"") | H23: =IFERROR(IF(INDEX('Controle de Entrega'!$H$6:$H$1575,MATCH($B23,'Controle de Entrega'!$M$6:$M$1575,0))=0,"",INDEX('Controle de Entrega'!$H$6:$H$1575,MATCH($B23,'Controle de Entrega'!$M$6:$M$1575,0))),"") | I23: =IFERROR(IF(INDEX('Controle de Entrega'!$I$6:$I$1575,MATCH($B23,'Controle de Entrega'!$M$6:$M$1575,0))=0,"",INDEX('Controle de Entrega'!$I$6:$I$1575,MATCH($B23,'Controle de Entrega'!$M$6:$M$1575,0))),"")
... B41: 30 | C41: =IFERROR(INDEX('Controle de Entrega'!$A$6:$A$1575,MATCH($B41,'Controle de Entrega'!$M$6:$M$1575,0)),"") | D41: =IFERROR(INDEX('Controle de Entrega'!$B$6:$B$1575,MATCH($B41,'Controle de Entrega'!$M$6:$M$1575,0)),"") | E41: =IFERROR(INDEX('Controle de Entrega'!$C$6:$C$1575,MATCH($B41,'Controle de Entrega'!$M$6:$M$1575,0)),"") | F41: =IFERROR(INDEX('Controle de Entrega'!$D$6:$D$1575,MATCH($B41,'Controle de Entrega'!$M$6:$M$1575,0)),"") | G41: =IFERROR(INDEX('Controle de Entrega'!$E$6:$E$1575,MATCH($B41,'Controle de Entrega'!$M$6:$M$1575,0)),"") | H41: =IFERROR(IF(INDEX('Controle de Entrega'!$H$6:$H$1575,MATCH($B41,'Controle de Entrega'!$M$6:$M$1575,0))=0,"",INDEX('Controle de Entrega'!$H$6:$H$1575,MATCH($B41,'Controle de Entrega'!$M$6:$M$1575,0))),"") | I41: =IFERROR(IF(INDEX('Controle de Entrega'!$I$6:$I$1575,MATCH($B41,'Controle de Entrega'!$M$6:$M$1575,0))=0,"",INDEX('Controle de Entrega'!$I$6:$I$1575,MATCH($B41,'Controle de Entrega'!$M$6:$M$1575,0))),"")
D42: TOTAL DE ITENS: | G42: =IF($D$6="","",COUNTIFS('Controle de Entrega'!$N$6:$N$1575,$D$6,'Controle de Entrega'!$G$6:$G$1575,$D$7)) -> 0
B45: Declaro, para os devidos fins, ter entregue na referente data os equipamentos relacionados acima, em perfeito estado de funcionamento, responsabilizando-me pela sua guarda e uso adequado, conforme as normas internas da empresa.
B50: _____________________________________ | F50: _____________________________________
B51: Assinatura do Técnico | F51: Assinatura do Responsável pelo Almoxarifado
B53: =IF($D$7="","",$C$9) -> 5 de abril de 2026

Sheet Ranking Clientes
A1: RANKING DE TÉCNICOS — EQUIPAMENTOS EM CLIENTES
A2: Lista para acompanhamento da MANUTENÇÃO/logística reversa: quais técnicos estão com mais equipamentos entregues diretamente a clientes (pendentes de devolução manual) no período.
B4: Data início: | C4: 46113 | D4: Data fim: | E4: 46142 | H4: =Técnicos!$C$5 -> Carlos Eduardo Lima | I4: =SUMIFS('Controle de Entrega'!$E$6:$E$1575,'Controle de Entrega'!$N$6:$N$1575,H4,'Controle de Entrega'!$G$6:$G$1575,">="&$C$4,'Controle de Entrega'!$G$6:$G$1575,"<="&$E$4,'Controle de Entrega'!$I$6:$I$1575,"CLIENTE*") -> 5 | J4: =SUMIFS('Controle de Entrega'!$E$6:$E$1575,'Controle de Entrega'!$N$6:$N$1575,H4,'Controle de Entrega'!$G$6:$G$1575,">="&$C$4,'Controle de Entrega'!$G$6:$G$1575,"<="&$E$4) -> 8 | K4: =I4-ROW()/100000000 -> 5 | L4: =RANK(K4,$K$4:$K$34) -> 1
H5: =Técnicos!$C$6 -> Rafael Souza Martins | I5: =SUMIFS('Controle de Entrega'!$E$6:$E$1575,'Controle de Entrega'!$N$6:$N$1575,H5,'Controle de Entrega'!$G$6:$G$1575,">="&$C$4,'Controle de Entrega'!$G$6:$G$1575,"<="&$E$4,'Controle de Entrega'!$I$6:$I$1575,"CLIENTE*") -> 3 | J5: =SUMIFS('Controle de Entrega'!$E$6:$E$1575,'Controle de Entrega'!$N$6:$N$1575,H5,'Controle de Entrega'!$G$6:$G$1575,">="&$C$4,'Controle de Entrega'!$G$6:$G$1575,"<="&$E$4) -> 7 | K5: =I5-ROW()/100000000 -> 2.9999999 | L5: =RANK(K5,$K$4:$K$34) -> 4
H6: =Técnicos!$C$7 -> Bruno Henrique Costa | I6: =SUMIFS('Controle de Entrega'!$E$6:$E$1575,'Controle de Entrega'!$N$6:$N$1575,H6,'Controle de Entrega'!$G$6:$G$1575,">="&$C$4,'Controle de Entrega'!$G$6:$G$1575,"<="&$E$4,'Controle de Entrega'!$I$6:$I$1575,"CLIENTE*") -> 0 | J6: =SUMIFS('Controle de Entrega'!$E$6:$E$1575,'Controle de Entrega'!$N$6:$N$1575,H6,'Controle de Entrega'!$G$6:$G$1575,">="&$C$4,'Controle de Entrega'!$G$6:$G$1575,"<="&$E$4) -> 3 | K6: =I6-ROW()/100000000 -> -6e-08 | L6: =RANK(K6,$K$4:$K$34) -> 8
A7: Posição | B7: Técnico | C7: Qtde. Roteadores em Clientes | D7: Qtde. total entregue | E7: % Clientes | H7: =Técnicos!$C$8 -> Diego Ferreira Alves | I7: =SUMIFS('Controle de Entrega'!$E$6:$E$1575,'Controle de Entrega'!$N$6:$N$1575,H7,'Controle de Entrega'!$G$6:$G$1575,">="&$C$4,'Controle de Entrega'!$G$6:$G$1575,"<="&$E$4,'Controle de Entrega'!$I$6:$I$1575,"CLIENTE*") -> 4 | J7: =SUMIFS('Controle de Entrega'!$E$6:$E$1575,'Controle de Entrega'!$N$6:$N$1575,H7,'Controle de Entrega'!$G$6:$G$1575,">="&$C$4,'Controle de Entrega'!$G$6:$G$1575,"<="&$E$4) -> 7 | K7: =I7-ROW()/100000000 -> 3.9999999 | L7: =RANK(K7,$K$4:$K$34) -> 3
A8: 1 | B8: =IFERROR(INDEX($H$4:$H$34,MATCH($A8,$L$4:$L$34,0)),"") -> Carlos Eduardo Lima | C8: =IFERROR(INDEX($I$4:$I$34,MATCH($A8,$L$4:$L$34,0)),"") -> 5 | D8: =IFERROR(INDEX($J$4:$J$34,MATCH($A8,$L$4:$L$34,0)),"") -> 8 | E8: =IF($D8=0,"-",$C8/$D8) -> 0.625 | H8: =Técnicos!$C$9 -> Marcos Vinícius Rocha | I8: =SUMIFS('Controle de Entrega'!$E$6:$E$1575,'Controle de Entrega'!$N$6:$N$1575,H8,'Controle de Entrega'!$G$6:$G$1575,">="&$C$4,'Controle de Entrega'!$G$6:$G$1575,"<="&$E$4,'Controle de Entrega'!$I$6:$I$1575,"CLIENTE*") -> 2 | J8: =SUMIFS('Controle de Entrega'!$E$6:$E$1575,'Controle de Entrega'!$N$6:$N$1575,H8,'Controle de Entrega'!$G$6:$G$1575,">="&$C$4,'Controle de Entrega'!$G$6:$G$1575,"<="&$E$4) -> 3 | K8: =I8-ROW()/100000000 -> 1.9999999 | L8: =RANK(K8,$K$4:$K$34) -> 5
A9: 2 | B9: =IFERROR(INDEX($H$4:$H$34,MATCH($A9,$L$4:$L$34,0)),"") -> Felipe Augusto Nunes | C9: =IFERROR(INDEX($I$4:$I$34,MATCH($A9,$L$4:$L$34,0)),"") -> 5 | D9: =IFERROR(INDEX($J$4:$J$34,MATCH($A9,$L$4:$L$34,0)),"") -> 7 | E9: =IF($D9=0,"-",$C9/$D9) -> 0.71428571 | H9: =Técnicos!$C$10 -> Felipe Augusto Nunes | I9: =SUMIFS('Controle de Entrega'!$E$6:$E$1575,'Controle de Entrega'!$N$6:$N$1575,H9,'Controle de Entrega'!$G$6:$G$1575,">="&$C$4,'Controle de Entrega'!$G$6:$G$1575,"<="&$E$4,'Controle de Entrega'!$I$6:$I$1575,"CLIENTE*") -> 5 | J9: =SUMIFS('Controle de Entrega'!$E$6:$E$1575,'Controle de Entrega'!$N$6:$N$1575,H9,'Controle de Entrega'!$G$6:$G$1575,">="&$C$4,'Controle de Entrega'!$G$6:$G$1575,"<="&$E$4) -> 7 | K9: =I9-ROW()/100000000 -> 4.9999999 | L9: =RANK(K9,$K$4:$K$34) -> 2
A10: 3 | B10: =IFERROR(INDEX($H$4:$H$34,MATCH($A10,$L$4:$L$34,0)),"") -> Diego Ferreira Alves | C10: =IFERROR(INDEX($I$4:$I$34,MATCH($A10,$L$4:$L$34,0)),"") -> 4 | D10: =IFERROR(INDEX($J$4:$J$34,MATCH($A10,$L$4:$L$34,0)),"") -> 7 | E10: =IF($D10=0,"-",$C10/$D10) -> 0.57142857 | H10: =Técnicos!$C$11 -> Thiago Ramos Silva | I10: =SUMIFS('Controle de Entrega'!$E$6:$E$1575,'Controle de Entrega'!$N$6:$N$1575,H10,'Controle de Entrega'!$G$6:$G$1575,">="&$C$4,'Controle de Entrega'!$G$6:$G$1575,"<="&$E$4,'Controle de Entrega'!$I$6:$I$1575,"CLIENTE*") -> 1 | J10: =SUMIFS('Controle de Entrega'!$E$6:$E$1575,'Controle de Entrega'!$N$6:$N$1575,H10,'Controle de Entrega'!$G$6:$G$1575,">="&$C$4,'Controle de Entrega'!$G$6:$G$1575,"<="&$E$4) -> 2 | K10: =I10-ROW()/100000000 -> 0.9999999 | L10: =RANK(K10,$K$4:$K$34) -> 7
A11: 4 | B11: =IFERROR(INDEX($H$4:$H$34,MATCH($A11,$L$4:$L$34,0)),"") -> Rafael Souza Martins | C11: =IFERROR(INDEX($I$4:$I$34,MATCH($A11,$L$4:$L$34,0)),"") -> 3 | D11: =IFERROR(INDEX($J$4:$J$34,MATCH($A11,$L$4:$L$34,0)),"") -> 7 | E11: =IF($D11=0,"-",$C11/$D11) -> 0.42857143 | H11: =Técnicos!$C$12 -> Lucas Pereira Gomes | I11: =SUMIFS('Controle de Entrega'!$E$6:$E$1575,'Controle de Entrega'!$N$6:$N$1575,H11,'Controle de Entrega'!$G$6:$G$1575,">="&$C$4,'Controle de Entrega'!$G$6:$G$1575,"<="&$E$4,'Controle de Entrega'!$I$6:$I$1575,"CLIENTE*") -> 2 | J11: =SUMIFS('Controle de Entrega'!$E$6:$E$1575,'Controle de Entrega'!$N$6:$N$1575,H11,'Controle de Entrega'!$G$6:$G$1575,">="&$C$4,'Controle de Entrega'!$G$6:$G$1575,"<="&$E$4) -> 3 | K11: =I11-ROW()/100000000 -> 1.9999999 | L11: =RANK(K11,$K$4:$K$34) -> 6
A12: 5 | B12: =IFERROR(INDEX($H$4:$H$34,MATCH($A12,$L$4:$L$34,0)),"") -> Marcos Vinícius Rocha | C12: =IFERROR(INDEX($I$4:$I$34,MATCH($A12,$L$4:$L$34,0)),"") -> 2 | D12: =IFERROR(INDEX($J$4:$J$34,MATCH($A12,$L$4:$L$34,0)),"") -> 3 | E12: =IF($D12=0,"-",$C12/$D12) -> 0.66666667 | H12: =Técnicos!$C$13 -> 0 | I12: =SUMIFS('Controle de Entrega'!$E$6:$E$1575,'Controle de Entrega'!$N$6:$N$1575,H12,'Controle de Entrega'!$G$6:$G$1575,">="&$C$4,'Controle de Entrega'!$G$6:$G$1575,"<="&$E$4,'Controle de Entrega'!$I$6:$I$1575,"CLIENTE*") -> 0 | J12: =SUMIFS('Controle de Entrega'!$E$6:$E$1575,'Controle de Entrega'!$N$6:$N$1575,H12,'Controle de Entrega'!$G$6:$G$1575,">="&$C$4,'Controle de Entrega'!$G$6:$G$1575,"<="&$E$4) -> 0 | K12: =I12-ROW()/100000000 -> -1.2e-07 | L12: =RANK(K12,$K$4:$K$34) -> 9
A13: 6 | B13: =IFERROR(INDEX($H$4:$H$34,MATCH($A13,$L$4:$L$34,0)),"") -> Lucas Pereira Gomes | C13: =IFERROR(INDEX($I$4:$I$34,MATCH($A13,$L$4:$L$34,0)),"") -> 2 | D13: =IFERROR(INDEX($J$4:$J$34,MATCH($A13,$L$4:$L$34,0)),"") -> 3 | E13: =IF($D13=0,"-",$C13/$D13) -> 0.66666667 | H13: =Técnicos!$C$14 -> 0 | I13: =SUMIFS('Controle de Entrega'!$E$6:$E$1575,'Controle de Entrega'!$N$6:$N$1575,H13,'Controle de Entrega'!$G$6:$G$1575,">="&$C$4,'Controle de Entrega'!$G$6:$G$1575,"<="&$E$4,'Controle de Entrega'!$I$6:$I$1575,"CLIENTE*") -> 0 | J13: =SUMIFS('Controle de Entrega'!$E$6:$E$1575,'Controle de Entrega'!$N$6:$N$1575,H13,'Controle de Entrega'!$G$6:$G$1575,">="&$C$4,'Controle de Entrega'!$G$6:$G$1575,"<="&$E$4) -> 0 | K13: =I13-ROW()/100000000 -> -1.3e-07 | L13: =RANK(K13,$K$4:$K$34) -> 10
A14: 7 | B14: =IFERROR(INDEX($H$4:$H$34,MATCH($A14,$L$4:$L$34,0)),"") -> Thiago Ramos Silva | C14: =IFERROR(INDEX($I$4:$I$34,MATCH($A14,$L$4:$L$34,0)),"") -> 1 | D14: =IFERROR(INDEX($J$4:$J$34,MATCH($A14,$L$4:$L$34,0)),"") -> 2 | E14: =IF($D14=0,"-",$C14/$D14) -> 0.5 | H14: =Técnicos!$C$15 -> 0 | I14: =SUMIFS('Controle de Entrega'!$E$6:$E$1575,'Controle de Entrega'!$N$6:$N$1575,H14,'Controle de Entrega'!$G$6:$G$1575,">="&$C$4,'Controle de Entrega'!$G$6:$G$1575,"<="&$E$4,'Controle de Entrega'!$I$6:$I$1575,"CLIENTE*") -> 0 | J14: =SUMIFS('Controle de Entrega'!$E$6:$E$1575,'Controle de Entrega'!$N$6:$N$1575,H14,'Controle de Entrega'!$G$6:$G$1575,">="&$C$4,'Controle de Entrega'!$G$6:$G$1575,"<="&$E$4) -> 0 | K14: =I14-ROW()/100000000 -> -1.4e-07 | L14: =RANK(K14,$K$4:$K$34) -> 11
A15: 8 | B15: =IFERROR(INDEX($H$4:$H$34,MATCH($A15,$L$4:$L$34,0)),"") -> Bruno Henrique Costa | C15: =IFERROR(INDEX($I$4:$I$34,MATCH($A15,$L$4:$L$34,0)),"") -> 0 | D15: =IFERROR(INDEX($J$4:$J$34,MATCH($A15,$L$4:$L$34,0)),"") -> 3 | E15: =IF($D15=0,"-",$C15/$D15) -> 0 | H15: =Técnicos!$C$16 -> 0 | I15: =SUMIFS('Controle de Entrega'!$E$6:$E$1575,'Controle de Entrega'!$N$6:$N$1575,H15,'Controle de Entrega'!$G$6:$G$1575,">="&$C$4,'Controle de Entrega'!$G$6:$G$1575,"<="&$E$4,'Controle de Entrega'!$I$6:$I$1575,"CLIENTE*") -> 0 | J15: =SUMIFS('Controle de Entrega'!$E$6:$E$1575,'Controle de Entrega'!$N$6:$N$1575,H15,'Controle de Entrega'!$G$6:$G$1575,">="&$C$4,'Controle de Entrega'!$G$6:$G$1575,"<="&$E$4) -> 0 | K15: =I15-ROW()/100000000 -> -1.5e-07 | L15: =RANK(K15,$K$4:$K$34) -> 12
A16: 9 | B16: =IFERROR(INDEX($H$4:$H$34,MATCH($A16,$L$4:$L$34,0)),"") -> 0 | C16: =IFERROR(INDEX($I$4:$I$34,MATCH($A16,$L$4:$L$34,0)),"") -> 0 | D16: =IFERROR(INDEX($J$4:$J$34,MATCH($A16,$L$4:$L$34,0)),"") -> 0 | E16: =IF($D16=0,"-",$C16/$D16) -> - | H16: =Técnicos!$C$17 -> 0 | I16: =SUMIFS('Controle de Entrega'!$E$6:$E$1575,'Controle de Entrega'!$N$6:$N$1575,H16,'Controle de Entrega'!$G$6:$G$1575,">="&$C$4,'Controle de Entrega'!$G$6:$G$1575,"<="&$E$4,'Controle de Entrega'!$I$6:$I$1575,"CLIENTE*") -> 0 | J16: =SUMIFS('Controle de Entrega'!$E$6:$E$1575,'Controle de Entrega'!$N$6:$N$1575,H16,'Controle de Entrega'!$G$6:$G$1575,">="&$C$4,'Controle de Entrega'!$G$6:$G$1575,"<="&$E$4) -> 0 | K16: =I16-ROW()/100000000 -> -1.6e-07 | L16: =RANK(K16,$K$4:$K$34) -> 13
A17: 10 | B17: =IFERROR(INDEX($H$4:$H$34,MATCH($A17,$L$4:$L$34,0)),"") -> 0 | C17: =IFERROR(INDEX($I$4:$I$34,MATCH($A17,$L$4:$L$34,0)),"") -> 0 | D17: =IFERROR(INDEX($J$4:$J$34,MATCH($A17,$L$4:$L$34,0)),"") -> 0 | E17: =IF($D17=0,"-",$C17/$D17) -> - | H17: =Técnicos!$C$18 -> 0 | I17: =SUMIFS('Controle de Entrega'!$E$6:$E$1575,'Controle de Entrega'!$N$6:$N$1575,H17,'Controle de Entrega'!$G$6:$G$1575,">="&$C$4,'Controle de Entrega'!$G$6:$G$1575,"<="&$E$4,'Controle de Entrega'!$I$6:$I$1575,"CLIENTE*") -> 0 | J17: =SUMIFS('Controle de Entrega'!$E$6:$E$1575,'Controle de Entrega'!$N$6:$N$1575,H17,'Controle de Entrega'!$G$6:$G$1575,">="&$C$4,'Controle de Entrega'!$G$6:$G$1575,"<="&$E$4) -> 0 | K17: =I17-ROW()/100000000 -> -1.7e-07 | L17: =RANK(K17,$K$4:$K$34) -> 14
A18: 11 | B18: =IFERROR(INDEX($H$4:$H$34,MATCH($A18,$L$4:$L$34,0)),"") -> 0 | C18: =IFERROR(INDEX($I$4:$I$34,MATCH($A18,$L$4:$L$34,0)),"") -> 0 | D18: =IFERROR(INDEX($J$4:$J$34,MATCH($A18,$L$4:$L$34,0)),"") -> 0 | E18: =IF($D18=0,"-",$C18/$D18) -> - | H18: =Técnicos!$C$19 -> 0 | I18: =SUMIFS('Controle de Entrega'!$E$6:$E$1575,'Controle de Entrega'!$N$6:$N$1575,H18,'Controle de Entrega'!$G$6:$G$1575,">="&$C$4,'Controle de Entrega'!$G$6:$G$1575,"<="&$E$4,'Controle de Entrega'!$I$6:$I$1575,"CLIENTE*") -> 0 | J18: =SUMIFS('Controle de Entrega'!$E$6:$E$1575,'Controle de Entrega'!$N$6:$N$1575,H18,'Controle de Entrega'!$G$6:$G$1575,">="&$C$4,'Controle de Entrega'!$G$6:$G$1575,"<="&$E$4) -> 0 | K18: =I18-ROW()/100000000 -> -1.8e-07 | L18: =RANK(K18,$K$4:$K$34) -> 15
A19: 12 | B19: =IFERROR(INDEX($H$4:$H$34,MATCH($A19,$L$4:$L$34,0)),"") -> 0 | C19: =IFERROR(INDEX($I$4:$I$34,MATCH($A19,$L$4:$L$34,0)),"") -> 0 | D19: =IFERROR(INDEX($J$4:$J$34,MATCH($A19,$L$4:$L$34,0)),"") -> 0 | E19: =IF($D19=0,"-",$C19/$D19) -> - | H19: =Técnicos!$C$20 -> 0 | I19: =SUMIFS('Controle de Entrega'!$E$6:$E$1575,'Controle de Entrega'!$N$6:$N$1575,H19,'Controle de Entrega'!$G$6:$G$1575,">="&$C$4,'Controle de Entrega'!$G$6:$G$1575,"<="&$E$4,'Controle de Entrega'!$I$6:$I$1575,"CLIENTE*") -> 0 | J19: =SUMIFS('Controle de Entrega'!$E$6:$E$1575,'Controle de Entrega'!$N$6:$N$1575,H19,'Controle de Entrega'!$G$6:$G$1575,">="&$C$4,'Controle de Entrega'!$G$6:$G$1575,"<="&$E$4) -> 0 | K19: =I19-ROW()/100000000 -> -1.9e-07 | L19: =RANK(K19,$K$4:$K$34) -> 16
A20: 13 | B20: =IFERROR(INDEX($H$4:$H$34,MATCH($A20,$L$4:$L$34,0)),"") -> 0 | C20: =IFERROR(INDEX($I$4:$I$34,MATCH($A20,$L$4:$L$34,0)),"") -> 0 | D20: =IFERROR(INDEX($J$4:$J$34,MATCH($A20,$L$4:$L$34,0)),"") -> 0 | E20: =IF($D20=0,"-",$C20/$D20) -> - | H20: =Técnicos!$C$21 -> 0 | I20: =SUMIFS('Controle de Entrega'!$E$6:$E$1575,'Controle de Entrega'!$N$6:$N$1575,H20,'Controle de Entrega'!$G$6:$G$1575,">="&$C$4,'Controle de Entrega'!$G$6:$G$1575,"<="&$E$4,'Controle de Entrega'!$I$6:$I$1575,"CLIENTE*") -> 0 | J20: =SUMIFS('Controle de Entrega'!$E$6:$E$1575,'Controle de Entrega'!$N$6:$N$1575,H20,'Controle de Entrega'!$G$6:$G$1575,">="&$C$4,'Controle de Entrega'!$G$6:$G$1575,"<="&$E$4) -> 0 | K20: =I20-ROW()/100000000 -> -2e-07 | L20: =RANK(K20,$K$4:$K$34) -> 17
A21: 14 | B21: =IFERROR(INDEX($H$4:$H$34,MATCH($A21,$L$4:$L$34,0)),"") -> 0 | C21: =IFERROR(INDEX($I$4:$I$34,MATCH($A21,$L$4:$L$34,0)),"") -> 0 | D21: =IFERROR(INDEX($J$4:$J$34,MATCH($A21,$L$4:$L$34,0)),"") -> 0 | E21: =IF($D21=0,"-",$C21/$D21) -> - | H21: =Técnicos!$C$22 -> 0 | I21: =SUMIFS('Controle de Entrega'!$E$6:$E$1575,'Controle de Entrega'!$N$6:$N$1575,H21,'Controle de Entrega'!$G$6:$G$1575,">="&$C$4,'Controle de Entrega'!$G$6:$G$1575,"<="&$E$4,'Controle de Entrega'!$I$6:$I$1575,"CLIENTE*") -> 0 | J21: =SUMIFS('Controle de Entrega'!$E$6:$E$1575,'Controle de Entrega'!$N$6:$N$1575,H21,'Controle de Entrega'!$G$6:$G$1575,">="&$C$4,'Controle de Entrega'!$G$6:$G$1575,"<="&$E$4) -> 0 | K21: =I21-ROW()/100000000 -> -2.1e-07 | L21: =RANK(K21,$K$4:$K$34) -> 18
A22: 15 | B22: =IFERROR(INDEX($H$4:$H$34,MATCH($A22,$L$4:$L$34,0)),"") -> 0 | C22: =IFERROR(INDEX($I$4:$I$34,MATCH($A22,$L$4:$L$34,0)),"") -> 0 | D22: =IFERROR(INDEX($J$4:$J$34,MATCH($A22,$L$4:$L$34,0)),"") -> 0 | E22: =IF($D22=0,"-",$C22/$D22) -> - | H22: =Técnicos!$C$23 -> 0 | I22: =SUMIFS('Controle de Entrega'!$E$6:$E$1575,'Controle de Entrega'!$N$6:$N$1575,H22,'Controle de Entrega'!$G$6:$G$1575,">="&$C$4,'Controle de Entrega'!$G$6:$G$1575,"<="&$E$4,'Controle de Entrega'!$I$6:$I$1575,"CLIENTE*") -> 0 | J22: =SUMIFS('Controle de Entrega'!$E$6:$E$1575,'Controle de Entrega'!$N$6:$N$1575,H22,'Controle de Entrega'!$G$6:$G$1575,">="&$C$4,'Controle de Entrega'!$G$6:$G$1575,"<="&$E$4) -> 0 | K22: =I22-ROW()/100000000 -> -2.2e-07 | L22: =RANK(K22,$K$4:$K$34) -> 19
A23: 16 | B23: =IFERROR(INDEX($H$4:$H$34,MATCH($A23,$L$4:$L$34,0)),"") -> 0 | C23: =IFERROR(INDEX($I$4:$I$34,MATCH($A23,$L$4:$L$34,0)),"") -> 0 | D23: =IFERROR(INDEX($J$4:$J$34,MATCH($A23,$L$4:$L$34,0)),"") -> 0 | E23: =IF($D23=0,"-",$C23/$D23) -> - | H23: =Técnicos!$C$24 -> 0 | I23: =SUMIFS('Controle de Entrega'!$E$6:$E$1575,'Controle de Entrega'!$N$6:$N$1575,H23,'Controle de Entrega'!$G$6:$G$1575,">="&$C$4,'Controle de Entrega'!$G$6:$G$1575,"<="&$E$4,'Controle de Entrega'!$I$6:$I$1575,"CLIENTE*") -> 0 | J23: =SUMIFS('Controle de Entrega'!$E$6:$E$1575,'Controle de Entrega'!$N$6:$N$1575,H23,'Controle de Entrega'!$G$6:$G$1575,">="&$C$4,'Controle de Entrega'!$G$6:$G$1575,"<="&$E$4) -> 0 | K23: =I23-ROW()/100000000 -> -2.3e-07 | L23: =RANK(K23,$K$4:$K$34) -> 20
A24: 17 | B24: =IFERROR(INDEX($H$4:$H$34,MATCH($A24,$L$4:$L$34,0)),"") -> 0 | C24: =IFERROR(INDEX($I$4:$I$34,MATCH($A24,$L$4:$L$34,0)),"") -> 0 | D24: =IFERROR(INDEX($J$4:$J$34,MATCH($A24,$L$4:$L$34,0)),"") -> 0 | E24: =IF($D24=0,"-",$C24/$D24) -> - | H24: =Técnicos!$C$25 -> 0 | I24: =SUMIFS('Controle de Entrega'!$E$6:$E$1575,'Controle de Entrega'!$N$6:$N$1575,H24,'Controle de Entrega'!$G$6:$G$1575,">="&$C$4,'Controle de Entrega'!$G$6:$G$1575,"<="&$E$4,'Controle de Entrega'!$I$6:$I$1575,"CLIENTE*") -> 0 | J24: =SUMIFS('Controle de Entrega'!$E$6:$E$1575,'Controle de Entrega'!$N$6:$N$1575,H24,'Controle de Entrega'!$G$6:$G$1575,">="&$C$4,'Controle de Entrega'!$G$6:$G$1575,"<="&$E$4) -> 0 | K24: =I24-ROW()/100000000 -> -2.4e-07 | L24: =RANK(K24,$K$4:$K$34) -> 21
